# Résolution de l'erreur dans le fichier `urls.py`

## Contexte :
Une erreur se produit dans le fichier `urls.py` de l'application Django. Cette erreur est causée par une faute de frappe dans le nom de l'argument `name` dans une des routes définies dans `urlpatterns`.

## Étapes de diagnostic :
1. **Analyse du fichier `urls.py` :**
   - Le fichier contient des définitions de routes pour une application Django.
   - La troisième route définit une URL dynamique avec un paramètre UUID pour afficher les détails d'une conversation.
   - Le nom du paramètre `name` associé à la vue `conversation_detail` est incorrectement écrit.

2. **Cause identifiée :**
   - Dans la route associée à l'URL `/create/`, il manque la lettre "n" dans le mot **`conversation`**, créant une erreur qui empêche la résolution correcte de la route :
     ```python
     path('create/', views.create_conversation, name='create_conversatio'),
     ```
   - La clé `name` est utilisée pour identifier chaque route, et une erreur dans cette chaîne de caractères provoque un dysfonctionnement.

## Solution :
1. **Correction de la faute de frappe** :
   - La chaîne de caractères associée à l'argument `name` a été corrigée. Le mot **`conversation`** a été corrigé dans la route concernée :
     ```python
     path('create/', views.create_conversation, name='create_conversation'),
     ```

2. **Code après correction :**
   ```python
   from django.urls import path
   from . import views

   urlpatterns = [
       path('', views.home, name='home'),
       path('create/', views.create_conversation, name='create_conversation'),
       path('<uuid:conversation_id>/', views.conversation_detail, name='conversation_detail'),
   ]
